Workbook

Sheet Summary
A1: calibre_review on loc-test: Ollama qwen3.5:4b vs Azure gpt-5.4-nano
A2: All figures below are formulas over the 'Run Metrics' and 'Compare Models' sheets. Blue = Ollama, orange = Azure in every chart.
A4: 1. Run performance (522 books per run)
A5: Metric | B5: Ollama qwen3.5:4b | C5: Azure gpt-5.4-nano | D5: Azure vs Ollama
A6: Wall-clock duration (min) | B6: ='Run Metrics'!G2/60 -> 32.021667 | C6: ='Run Metrics'!G3/60 -> 32.691667 | D6: =IFERROR(C6/B6-1,"n/a") -> 0.020923333
A7: Time spent in AI calls (min) | B7: ='Run Metrics'!H2/60 -> 24.548333 | C7: ='Run Metrics'!H3/60 -> 26.288333 | D7: =IFERROR(C7/B7-1,"n/a") -> 0.070880576
A8: Non-AI overhead (min) | B8: =('Run Metrics'!G2-'Run Metrics'!H2)/60 -> 7.4733333 | C8: =('Run Metrics'!G3-'Run Metrics'!H3)/60 -> 6.4033333 | D8: =IFERROR(C8/B8-1,"n/a") -> -0.14317574
A9: Books per minute | B9: ='Run Metrics'!E2/('Run Metrics'!G2/60) -> 16.301463 | C9: ='Run Metrics'!E3/('Run Metrics'!G3/60) -> 15.967372 | D9: =IFERROR(C9/B9-1,"n/a") -> -0.02049452
A10: AI calls | B10: ='Run Metrics'!I2 -> 522 | C10: ='Run Metrics'!I3 -> 543 | D10: =IFERROR(C10/B10-1,"n/a") -> 0.040229885
A11: Successful calls | B11: ='Run Metrics'!K2 -> 522 | C11: ='Run Metrics'!K3 -> 522 | D11: =IFERROR(C11/B11-1,"n/a") -> 0
A12: Failed calls (content filter) | B12: ='Run Metrics'!L2 -> 0 | C12: ='Run Metrics'!L3 -> 21 | D12: n/a
A13: Failure rate | B13: ='Run Metrics'!L2/'Run Metrics'!I2 -> 0 | C13: ='Run Metrics'!L3/'Run Metrics'!I3 -> 0.038674033 | D13: n/a
A14: Call time: min (s) | B14: ='Run Metrics'!O2 -> 1.4 | C14: ='Run Metrics'!O3 -> 1.65 | D14: =IFERROR(C14/B14-1,"n/a") -> 0.17857143
A15: Call time: median (s) | B15: ='Run Metrics'!P2 -> 2.81 | C15: ='Run Metrics'!P3 -> 2.82 | D15: =IFERROR(C15/B15-1,"n/a") -> 0.0035587189
A16: Call time: mean (s) | B16: ='Run Metrics'!Q2 -> 2.82 | C16: ='Run Metrics'!Q3 -> 2.9 | D16: =IFERROR(C16/B16-1,"n/a") -> 0.028368794
A17: Call time: p95 (s) | B17: ='Run Metrics'!R2 -> 3.29 | C17: ='Run Metrics'!R3 -> 3.58 | D17: =IFERROR(C17/B17-1,"n/a") -> 0.088145897
A18: Call time: max (s) | B18: ='Run Metrics'!S2 -> 8.15 | C18: ='Run Metrics'!S3 -> 4.06 | D18: =IFERROR(C18/B18-1,"n/a") -> -0.50184049
A19: Input tokens | B19: ='Run Metrics'!T2 -> 1837099 | C19: ='Run Metrics'!T3 -> 1748695 | D19: =IFERROR(C19/B19-1,"n/a") -> -0.048121522
A20: Output tokens | B20: ='Run Metrics'!U2 -> 28132 | C20: ='Run Metrics'!U3 -> 26745 | D20: =IFERROR(C20/B20-1,"n/a") -> -0.049303285
A21: Total tokens | B21: ='Run Metrics'!T2+'Run Metrics'!U2+'Run Metrics'!V2 -> 1865231 | C21: ='Run Metrics'!T3+'Run Metrics'!U3+'Run Metrics'!V3 -> 1775440 | D21: =IFERROR(C21/B21-1,"n/a") -> -0.048139346
A22: Reasoning tokens | B22: ='Run Metrics'!V2 -> 0 | C22: ='Run Metrics'!V3 -> 0 | D22: n/a
A23: Azure vs Ollama = Azure / Ollama - 1 (negative = Azure lower). Fewer/lower is better for time, calls and tokens.
A26: 2. Accuracy on the injected errors (rows where field is not 'other')
A27: Outcome | B27: Ollama qwen3.5:4b | C27: Azure gpt-5.4-nano | D27: Azure - Ollama
A28: fixed | B28: =COUNTIFS('Compare Models'!$B$2:$B$255,"<>other",'Compare Models'!$F$2:$F$255,$A28) -> 23 | C28: =COUNTIFS('Compare Models'!$B$2:$B$255,"<>other",'Compare Models'!$H$2:$H$255,$A28) -> 25 | D28: =C28-B28 -> 2
A29: flagged, other value | B29: =COUNTIFS('Compare Models'!$B$2:$B$255,"<>other",'Compare Models'!$F$2:$F$255,$A29) -> 8 | C29: =COUNTIFS('Compare Models'!$B$2:$B$255,"<>other",'Compare Models'!$H$2:$H$255,$A29) -> 7 | D29: =C29-B29 -> -1
A30: ignored (by design) | B30: =COUNTIFS('Compare Models'!$B$2:$B$255,"<>other",'Compare Models'!$F$2:$F$255,$A30) -> 11 | C30: =COUNTIFS('Compare Models'!$B$2:$B$255,"<>other",'Compare Models'!$H$2:$H$255,$A30) -> 11 | D30: =C30-B30 -> 0
A31: metadata also wrong | B31: =COUNTIFS('Compare Models'!$B$2:$B$255,"<>other",'Compare Models'!$F$2:$F$255,$A31) -> 10 | C31: =COUNTIFS('Compare Models'!$B$2:$B$255,"<>other",'Compare Models'!$H$2:$H$255,$A31) -> 10 | D31: =C31-B31 -> 0
A32: ok, nothing proposed | B32: =COUNTIFS('Compare Models'!$B$2:$B$255,"<>other",'Compare Models'!$F$2:$F$255,$A32) -> 6 | C32: =COUNTIFS('Compare Models'!$B$2:$B$255,"<>other",'Compare Models'!$H$2:$H$255,$A32) -> 8 | D32: =C32-B32 -> 2
A33: correct, nothing proposed | B33: =COUNTIFS('Compare Models'!$B$2:$B$255,"<>other",'Compare Models'!$F$2:$F$255,$A33) -> 1 | C33: =COUNTIFS('Compare Models'!$B$2:$B$255,"<>other",'Compare Models'!$H$2:$H$255,$A33) -> 1 | D33: =C33-B33 -> 0
A34: FALSE ALARM | B34: =COUNTIFS('Compare Models'!$B$2:$B$255,"<>other",'Compare Models'!$F$2:$F$255,$A34) -> 4 | C34: =COUNTIFS('Compare Models'!$B$2:$B$255,"<>other",'Compare Models'!$H$2:$H$255,$A34) -> 2 | D34: =C34-B34 -> -2
A35: MISSED | B35: =COUNTIFS('Compare Models'!$B$2:$B$255,"<>other",'Compare Models'!$F$2:$F$255,$A35) -> 2 | C35: =COUNTIFS('Compare Models'!$B$2:$B$255,"<>other",'Compare Models'!$H$2:$H$255,$A35) -> 1 | D35: =C35-B35 -> -1
A36: Total injected rows | B36: =SUM(B28:B35) -> 65 | C36: =SUM(C28:C35) -> 65 | D36: =C36-B36 -> 0
A37: Wrong outcomes (FALSE ALARM + MISSED) | B37: =B34+B35 -> 6 | C37: =C34+C35 -> 3 | D37: =C37-B37 -> -3
A38: Wrong-outcome rate | B38: =B37/B36 -> 0.092307692 | C38: =C37/C36 -> 0.046153846 | D38: =C38-B38 -> -0.046153846
A39: Flagged but with a different value | B39: =B29 -> 8 | C39: =C29 -> 7 | D39: =C39-B39 -> -1
A40: 'ignored (by design)' and 'ok/correct, nothing proposed' are expected behaviours, not errors. Wrong-outcome counts only FALSE ALARM and MISSED.
A43: 3. 'Fixed' by field (authors and title errors)
A44: Field | B44: Ollama fixed | C44: Azure fixed | D44: Injected rows
A45: authors | B45: =COUNTIFS('Compare Models'!$B$2:$B$255,$A45,'Compare Models'!$F$2:$F$255,"fixed") -> 12 | C45: =COUNTIFS('Compare Models'!$B$2:$B$255,$A45,'Compare Models'!$H$2:$H$255,"fixed") -> 13 | D45: =COUNTIFS('Compare Models'!$B$2:$B$255,$A45) -> 20
...

Sheet Run Metrics
A1: started | B1: text_ai | C1: image_ai | D1: books | E1: books_done | F1: stopped | G1: duration_s | H1: ai_seconds | I1: calls | J1: books_with_ai | K1: calls_ok | L1: calls_failed | M1: failures | N1: not_stop_finish | O1: min_s | P1: median_s | Q1: mean_s | R1: p95_s | S1: max_s | T1: input_tokens | U1: output_tokens | V1: reasoning_tokens
A2: 46294.906 | B2: ollama:qwen3.5:4b | C2: ollama:qwen3.5:4b | D2: 522 | E2: 522 | F2: =FALSE() -> FALSE | G2: 1921.3 | H2: 1472.9 | I2: 522 | J2: 522 | K2: 522 | L2: 0 | N2: 0 | O2: 1.4 | P2: 2.81 | Q2: 2.82 | R2: 3.29 | S2: 8.15 | T2: 1837099 | U2: 28132 | V2: 0
A3: 46294.935 | B3: azure:gpt-5.4-nano | C3: azure:gpt-5.4-nano | D3: 522 | E3: 522 | F3: =FALSE() -> FALSE | G3: 1961.5 | H3: 1577.3 | I3: 543 | J3: 522 | K3: 522 | L3: 21 | M3: filtered=21 | N3: 0 | O3: 1.65 | P3: 2.82 | Q3: 2.9 | R3: 3.58 | S3: 4.06 | T3: 1748695 | U3: 26745 | V3: 0

Sheet Compare Models
A1: book_id | B1: field | C1: kind | D1: original | E1: wrong | F1: ollama:qwen3.5:4b result | G1: ollama:qwen3.5:4b proposed | H1: azure:gpt-5.4-nano result | I1: azure:gpt-5.4-nano proposed
A2: 550 | B2: authors | C2: typo | D2: Charles Sainte-Foi | E2: Charles Saintee-Foi | F2: fixed | G2: Charles Sainte-Foi | H2: fixed | I2: Charles Sainte-Foi
A3: 559 | B3: title | C3: other book | D3: Elements of the Theory and Practice of Chymistry, 5th ed. | E3: The Female Quixote; or, The Adventures of Arabella, v. 1-2 | F3: flagged, other value | G3: Elements of the Theory and Practice of Chymistry | H3: flagged, other value | I3: Elements of the Theory and Practice of Chymistry
A4: 563 | B4: title | C4: other book | D4: A Little Dinner at Timmins's | E4: Devereux — Volume 02 | F4: fixed | G4: A Little Dinner at Timmins's | H4: fixed | I4: A Little Dinner at Timmins's
A5: 566 | B5: title | C5: typo | D5: A System of Midwifery | E5: A Syste of Midwifery | F5: fixed | G5: A System of Midwifery | H5: fixed | I5: A System of Midwifery
A6: 568 | B6: series | C6: not a numbered series | E6: The Works [2] | F6: ignored (by design) | H6: ignored (by design)
A7: 581 | B7: authors | C7: unknown | D7: Duchess of Margaret Cavendish Newcastle | E7: Unknown | F7: flagged, other value | G7: Margaret Cavendish | H7: fixed | I7: Duchess of Margaret Cavendish Newcastle
A8: 593 | B8: title | C8: truncated | D8: Chasing the Sun | E8: Chasing | F8: fixed | G8: Chasing the Sun | H8: fixed | I8: Chasing the Sun
A9: 598 | B9: authors | C9: other book | D9: William Falconer | E9: T. S. Arthur | F9: fixed | G9: William Falconer | H9: fixed | I9: William Falconer
A10: 626 | B10: authors | C10: unknown | D10: Gervase Markham | E10: Unknown | F10: fixed | G10: Gervase Markham | H10: fixed | I10: Gervase Markham
A11: 627 | B11: authors | C11: unknown | D11: Charlotte Lennox | E11: Unknown | F11: fixed | G11: Charlotte Lennox | H11: fixed | I11: Charlotte Lennox
A12: 630 | B12: title | C12: typo | D12: Home Life in Russia, Volumes 1 and 2 / [Dead Souls] | E12: Home Life in Russia, Volumess 1 and 2 / [Dead Souls] | F12: flagged, other value | G12: Home Life in Russia | H12: flagged, other value | I12: Home Life in Russia, Volumes 1 and 2
A13: 633 | B13: authors | C13: surname first | D13: Wilhelm Hauff | E13: Hauff Wilhelm | F13: ignored (by design) | H13: ignored (by design)
A14: 634 | B14: authors | C14: unknown | D14: Frederick Marryat | E14: Unknown | F14: fixed | G14: Frederick Marryat | H14: fixed | I14: Frederick Marryat
A15: 634 | B15: title | C15: unknown | D15: The Mission | E15: Unknown | F15: fixed | G15: The Mission | H15: fixed | I15: The Mission
A16: 635 | B16: series | C16: wrong number | D16: 6 | E16: The Works [4] | F16: MISSED | H16: flagged, other value | I16: Project Gutenberg eBook [9594]
A17: 636 | B17: authors | C17: surname first | D17: Sydney Smith | E17: Smith Sydney | F17: ignored (by design) | H17: ignored (by design)
A18: 642 | B18: authors | C18: typo | D18: John Franklin | E18: John Franlkin | F18: fixed | G18: John Franklin | H18: fixed | I18: John Franklin
A19: 671 | B19: authors | C19: surname first | D19: John Foxe | E19: Foxe John | F19: ignored (by design) | H19: ignored (by design)
A20: 695 | B20: authors | C20: surname first | D20: William Black | E20: Black William | F20: ignored (by design) | H20: ignored (by design)
A21: 696 | B21: authors | C21: other book | D21: Charles Lever | E21: Duke of Arthur Wellesley Wellington | F21: fixed | G21: Charles Lever | H21: fixed | I21: Charles Lever
A22: 697 | B22: authors | C22: surname first | D22: Maude Alma | E22: Alma Maude | F22: ignored (by design) | H22: ignored (by design)
A23: 726 | B23: title | C23: unknown | D23: Riches have wings; or, A tale for the rich and poor | E23: Unknown | F23: fixed | G23: Riches have wings; or, A tale for the rich and poor | H23: fixed | I23: Riches have wings; or, A tale for the rich and poor
A24: 734 | B24: title | C24: all caps | D24: Gaut Gurley; Or, the Trappers of Umbagog: A Tale of Border Life | E24: GAUT GURLEY; OR, THE TRAPPERS OF UMBAGOG: A TALE OF BORDER LIFE | F24: ignored (by design) | H24: ignored (by design)
A25: 746 | B25: authors | C25: other book | D25: Jr. Horatio Alger | E25: George Augustus Sala | F25: fixed | G25: Horatio Alger Jr. | H25: fixed | I25: Horatio Alger, Jr.
A26: 753 | B26: title | C26: typo | D26: Some Private Views | E26: Som Private Views | F26: fixed | G26: Some Private Views | H26: fixed | I26: Some Private Views
A27: 777 | B27: title | C27: all caps | D27: Equality | E27: EQUALITY | F27: ignored (by design) | H27: ignored (by design)
A28: 793 | B28: series | C28: number matches the title | D28: 5 | E28: The Works [5] | F28: correct, nothing proposed | H28: correct, nothing proposed
A29: 800 | B29: title | C29: truncated | D29: Monsieur de Camors — Complete | E29: Monsieur de | F29: fixed | G29: Monsieur de Camors — Complete | H29: fixed | I29: Monsieur de Camors — Complete
A30: 810 | B30: title | C30: unknown | D30: Evenings at Donaldson Manor; Or, The Christmas Guest | E30: Unknown | F30: fixed | G30: Evenings at Donaldson Manor; Or, The Christmas Guest | H30: fixed | I30: Evenings at Donaldson Manor; Or, The Christmas Guest
A31: 818 | B31: authors | C31: other book | D31: Aaron Burr | E31: Madeline Leslie & A. R. Baker | F31: fixed | G31: Aaron Burr | H31: flagged, other value | I31: Matthew L. Davis
A32: 820 | B32: title | C32: all caps | D32: The Poems of Richard Corbet, late bishop of Oxford and of Norwich / 4th edition | E32: THE POEMS OF RICHARD CORBET, LATE BISHOP OF OXFORD AND OF NORWICH / 4TH EDITION | F32: flagged, other value | G32: The Poems of Richard Corbet | H32: flagged, other value | I32: The Poems of Richard Corbet, late bishop of Oxford and of Norwich
A33: 829 | B33: title | C33: typo | D33: The History and Remarkable Life of the Truly Honourable Colonel Jacque, Commonly Called Colonel Jack | E33: The History and Remarkable Life of the Truly Honourable Colonel Jacque, Commonly Called Colonl Jack | F33: fixed | G33: The History and Remarkable Life of the Truly Honourable Colonel Jacque, Commonly Called Colonel Jack | H33: fixed | I33: The History and Remarkable Life of the Truly Honourable Colonel Jacque, Commonly Called Colonel Jack
A34: 834 | B34: series | C34: not a numbered series | E34: The Works [1] | F34: ignored (by design) | H34: ignored (by design)
A35: 877 | B35: title | C35: truncated | D35: The sacred theory of the Earth, Volume 1 (of 2) | E35: The sacred theory of the | F35: flagged, other value | G35: The Sacred Theory of the Earth | H35: fixed | I35: The sacred theory of the Earth, Volume 1 (of 2)
A36: 882 | B36: authors | C36: surname first | D36: W. Hamilton Gibson | E36: Gibson W. Hamilton | F36: ignored (by design) | H36: ignored (by design)
A37: 894 | B37: title | C37: other book | D37: In Trust: The Story of a Lady and Her Lover | E37: The Percheron horse | F37: fixed | G37: In Trust: The Story of a Lady and Her Lover | H37: fixed | I37: In Trust: The Story of a Lady and Her Lover
A38: 898 | B38: authors | C38: typo | D38: Frederick Marryat | E38: Frederickk Marryat | F38: fixed | G38: Frederick Marryat | H38: fixed | I38: Frederick Marryat
A39: 899 | B39: series | C39: wrong number | D39: 6 | E39: The Works [3] | F39: MISSED | H39: MISSED
A40: 912 | B40: authors | C40: typo | D40: Hugh Blair Grigsby | E40: Hugh Blar Grigsby | F40: fixed | G40: Hugh Blair Grigsby | H40: fixed | I40: Hugh Blair Grigsby
...

Sheet Script
A1: Line | B1: loc-test_run_metrics.py
A2: 1 | B2: """Performance metrics of the Metadata Review runs on loc-test, from the review's performance log.
A3: 2
A4: 3 | B4: For each review run over loc-test (a run whose book count equals loc-test's): the AI models,
A5: 4 | B5: wall-clock duration, books done, AI calls by outcome (ok / error / too_long / ...), the time
A6: 5 | B6: per call (min, median, mean, p95, max), the slowest and fastest calls with their book, and
A7: 6 | B7: the tokens. With two or more runs, a side-by-side table closes the report.
A8: 7
A9: 8 | B9: C:\\Github\\CalibreDedup\\.venv\\Scripts\\python.exe C:\\Calibre\\loc-test_run_metrics.py [--last N]
A10: 9
A11: 10 | B11: Default: the last 2 runs. The perf log gives a book only as its number in the run; books are
A12: 11 | B12: read in id order (library.read_books) and loc-test has no AIReviewed tag, so number n is the
A13: 12 | B13: n-th book id of loc-test/metadata.db. Nothing is written to the library; one row per run goes
A14: 13 | B14: to loc-test_run_metrics.csv beside this script.
A15: 14 | B15: """
A16: 15 | B16: import csv
A17: 16 | B17: import json
A18: 17 | B18: import sqlite3
A19: 18 | B19: import statistics
A20: 19 | B20: import sys
A21: 20 | B21: from pathlib import Path
A22: 21
A23: 22 | B23: HERE = Path(__file__).resolve().parent
A24: 23 | B24: LIBRARY = HERE / "loc-test"
A25: 24 | B25: REPORT = HERE / "loc-test_run_metrics.csv"
A26: 25 | B26: PERF = Path.home() / ".CalibreDedup" / "calibre_review_perf.log"
A27: 26 | B27: TOP = 5
A28: 27
A29: 28
A30: 29 | B30: def events() -> list[dict]:
A31: 30 | B31: """Every event of the perf log, rotated files included, oldest first."""
A32: 31 | B32: files = sorted(PERF.parent.glob(PERF.name + ".*"), key=lambda p: -int(p.suffix[1:])) + [PERF]
A33: 32 | B33: out = []
A34: 33 | B34: for f in files:
A35: 34 | B35: if f.is_file():
A36: 35 | B36: with f.open(encoding="utf-8") as fh:
A37: 36 | B37: out += [json.loads(line) for line in fh if line.strip()]
A38: 37 | B38: return out
A39: 38
A40: 39
...
